2022-04-21 15:30:23,019 INFO    MainThread:327850 [internal.py:wandb_internal():87] W&B internal server running at pid: 327850, started at: 2022-04-21 15:30:23.019142
2022-04-21 15:30:23,021 DEBUG   HandlerThread:327850 [handler.py:handle_request():130] handle_request: check_version
2022-04-21 15:30:23,021 DEBUG   SenderThread:327850 [sender.py:send():234] send: header
2022-04-21 15:30:23,021 DEBUG   SenderThread:327850 [sender.py:send_request():248] send_request: check_version
2022-04-21 15:30:23,021 INFO    WriterThread:327850 [datastore.py:open_for_write():77] open: /home/tbertrand/Bureau/ULM_4channel_pull/wandb/run-20220421_153022-2bxjvwmf/run-2bxjvwmf.wandb
2022-04-21 15:30:23,055 DEBUG   SenderThread:327850 [sender.py:send():234] send: run
2022-04-21 15:30:45,326 WARNING MainThread:327850 [internal.py:wandb_internal():146] Internal process interrupt: 1
2022-04-21 15:30:45,522 WARNING MainThread:327850 [internal.py:wandb_internal():146] Internal process interrupt: 2
2022-04-21 15:30:45,523 ERROR   MainThread:327850 [internal.py:wandb_internal():149] Internal process interrupted.
2022-04-21 15:30:46,065 INFO    WriterThread:327850 [datastore.py:close():281] close: /home/tbertrand/Bureau/ULM_4channel_pull/wandb/run-20220421_153022-2bxjvwmf/run-2bxjvwmf.wandb
2022-04-21 15:30:46,082 INFO    HandlerThread:327850 [handler.py:finish():731] shutting down handler
2022-04-21 15:30:56,291 ERROR   SenderThread:327850 [retry.py:__call__():126] Retry attempt failed:
Traceback (most recent call last):
  File "/home/tbertrand/Bureau/ULM_4channel_pull/lib/python3.8/site-packages/urllib3/connectionpool.py", line 449, in _make_request
    six.raise_from(e, None)
  File "<string>", line 3, in raise_from
  File "/home/tbertrand/Bureau/ULM_4channel_pull/lib/python3.8/site-packages/urllib3/connectionpool.py", line 444, in _make_request
    httplib_response = conn.getresponse()
  File "/home/tbertrand/anaconda3/lib/python3.8/http/client.py", line 1347, in getresponse
    response.begin()
  File "/home/tbertrand/anaconda3/lib/python3.8/http/client.py", line 307, in begin
    version, status, reason = self._read_status()
  File "/home/tbertrand/anaconda3/lib/python3.8/http/client.py", line 268, in _read_status
    line = str(self.fp.readline(_MAXLINE + 1), "iso-8859-1")
  File "/home/tbertrand/anaconda3/lib/python3.8/socket.py", line 669, in readinto
    return self._sock.recv_into(b)
  File "/home/tbertrand/anaconda3/lib/python3.8/ssl.py", line 1241, in recv_into
    return self.read(nbytes, buffer)
  File "/home/tbertrand/anaconda3/lib/python3.8/ssl.py", line 1099, in read
    return self._sslobj.read(len, buffer)
socket.timeout: The read operation timed out

During handling of the above exception, another exception occurred:

Traceback (most recent call last):
  File "/home/tbertrand/Bureau/ULM_4channel_pull/lib/python3.8/site-packages/requests/adapters.py", line 440, in send
    resp = conn.urlopen(
  File "/home/tbertrand/Bureau/ULM_4channel_pull/lib/python3.8/site-packages/urllib3/connectionpool.py", line 785, in urlopen
    retries = retries.increment(
  File "/home/tbertrand/Bureau/ULM_4channel_pull/lib/python3.8/site-packages/urllib3/util/retry.py", line 550, in increment
    raise six.reraise(type(error), error, _stacktrace)
  File "/home/tbertrand/Bureau/ULM_4channel_pull/lib/python3.8/site-packages/urllib3/packages/six.py", line 770, in reraise
    raise value
  File "/home/tbertrand/Bureau/ULM_4channel_pull/lib/python3.8/site-packages/urllib3/connectionpool.py", line 703, in urlopen
    httplib_response = self._make_request(
  File "/home/tbertrand/Bureau/ULM_4channel_pull/lib/python3.8/site-packages/urllib3/connectionpool.py", line 451, in _make_request
    self._raise_timeout(err=e, url=url, timeout_value=read_timeout)
  File "/home/tbertrand/Bureau/ULM_4channel_pull/lib/python3.8/site-packages/urllib3/connectionpool.py", line 340, in _raise_timeout
    raise ReadTimeoutError(
urllib3.exceptions.ReadTimeoutError: HTTPSConnectionPool(host='api.wandb.ai', port=443): Read timed out. (read timeout=10)

During handling of the above exception, another exception occurred:

Traceback (most recent call last):
  File "/home/tbertrand/Bureau/ULM_4channel_pull/lib/python3.8/site-packages/wandb/sdk/lib/retry.py", line 102, in __call__
    result = self._call_fn(*args, **kwargs)
  File "/home/tbertrand/Bureau/ULM_4channel_pull/lib/python3.8/site-packages/wandb/sdk/internal/internal_api.py", line 141, in execute
    return self.client.execute(*args, **kwargs)
  File "/home/tbertrand/Bureau/ULM_4channel_pull/lib/python3.8/site-packages/wandb/vendor/gql-0.2.0/gql/client.py", line 52, in execute
    result = self._get_result(document, *args, **kwargs)
  File "/home/tbertrand/Bureau/ULM_4channel_pull/lib/python3.8/site-packages/wandb/vendor/gql-0.2.0/gql/client.py", line 60, in _get_result
    return self.transport.execute(document, *args, **kwargs)
  File "/home/tbertrand/Bureau/ULM_4channel_pull/lib/python3.8/site-packages/wandb/vendor/gql-0.2.0/gql/transport/requests.py", line 38, in execute
    request = requests.post(self.url, **post_args)
  File "/home/tbertrand/Bureau/ULM_4channel_pull/lib/python3.8/site-packages/requests/api.py", line 117, in post
    return request('post', url, data=data, json=json, **kwargs)
  File "/home/tbertrand/Bureau/ULM_4channel_pull/lib/python3.8/site-packages/requests/api.py", line 61, in request
    return session.request(method=method, url=url, **kwargs)
  File "/home/tbertrand/Bureau/ULM_4channel_pull/lib/python3.8/site-packages/requests/sessions.py", line 529, in request
    resp = self.send(prep, **send_kwargs)
  File "/home/tbertrand/Bureau/ULM_4channel_pull/lib/python3.8/site-packages/requests/sessions.py", line 645, in send
    r = adapter.send(request, **kwargs)
  File "/home/tbertrand/Bureau/ULM_4channel_pull/lib/python3.8/site-packages/requests/adapters.py", line 532, in send
    raise ReadTimeout(e, request=request)
requests.exceptions.ReadTimeout: HTTPSConnectionPool(host='api.wandb.ai', port=443): Read timed out. (read timeout=10)
2022-04-21 15:32:37,891 INFO    SenderThread:327850 [dir_watcher.py:__init__():169] watching files in: /home/tbertrand/Bureau/ULM_4channel_pull/wandb/run-20220421_153022-2bxjvwmf/files
2022-04-21 15:32:37,891 INFO    SenderThread:327850 [sender.py:_start_run_threads():804] run started: 2bxjvwmf with start time 1650547822
2022-04-21 15:32:37,891 INFO    SenderThread:327850 [sender.py:finish():1070] shutting down sender
2022-04-21 15:32:37,891 INFO    SenderThread:327850 [dir_watcher.py:finish():283] shutting down directory watcher
2022-04-21 15:32:38,892 INFO    SenderThread:327850 [dir_watcher.py:finish():313] scan: /home/tbertrand/Bureau/ULM_4channel_pull/wandb/run-20220421_153022-2bxjvwmf/files
2022-04-21 15:32:38,893 INFO    SenderThread:327850 [dir_watcher.py:finish():327] scan save: /home/tbertrand/Bureau/ULM_4channel_pull/wandb/run-20220421_153022-2bxjvwmf/files/config.yaml config.yaml
2022-04-21 15:32:38,893 INFO    SenderThread:327850 [file_pusher.py:finish():177] shutting down file pusher
2022-04-21 15:32:38,893 INFO    SenderThread:327850 [file_pusher.py:join():182] waiting for file pusher
2022-04-21 15:32:39,684 INFO    Thread-10 :327850 [upload_job.py:push():137] Uploaded file /home/tbertrand/Bureau/ULM_4channel_pull/wandb/run-20220421_153022-2bxjvwmf/files/config.yaml
2022-04-21 15:32:40,272 INFO    MainThread:327850 [internal.py:handle_exit():77] Internal process exited
